Workbook

Sheet 說明
B2: 新竹排球館｜開館報價比價清單
B3: 查價日期：2026/10/21（網路刊登價，實際價格、含稅、運費請以賣家或廠商報價為準）
B5: 怎麼用 | C5: 1. 在「預算總表」黃底格調整場地假設（面積、燈具數、風扇數）。 2. 在「比價清單」的「選用」欄填 Y，該項目就會加總到預算總表；同一品項只選一個。 3. 找廠商估價後，填進「廠商報價追蹤」。 4. 「排球人口推估」黃底格是假設值，問卷或官方資料出來後直接改，結果會自動更新。
B6: 顏色說明 | C6: 藍字＝查到的價格或資料（輸入值） 黑字＝公式 綠字＝引用其他工作表 黃底＝假設值，請依實際情況修改
B7: 網拍低價注意 | C7: 網拍上的運動地膠、排球柱有很多是家用或練習等級，耐用度和安全性不一定適合營業場館。比價時請確認：厚度、是否有運動地板認證、保固、是否含施工。
B8: 大型吊扇注意 | C8: 7.3 m 的大型工業吊扇（HVLS）在網拍上標 1,000–5,000 元多半是訂金或零件價，實際要找廠商連安裝、結構評估一起報價。
B9: 還沒有價格的項目 | C9: 專業運動地板（Enlio、Taraflex）、比賽用排球網、裁判台、預約系統月費、廁所淋浴、法規變更、保險，這些要向廠商詢價，已列在「廠商報價追蹤」。
B10: 候選廠房 | C10: 廠房、倉庫候選物件（高度、大小、適合幾面、地點、價格）已移到同資料夾的「廠房搜尋清單.xlsx」，以那份為準。

Sheet 預算總表
A1: 開辦預算總表（元）
A3: 場地假設（黃底可改）
A4: 1 面場地板面積（㎡） | B4: 360 | C4: 24 × 15 m（球場＋四周 3 m 緩衝）
A5: 2 面場地板面積（㎡） | B5: 672 | C5: 約 28 × 24 m（兩面並排、中間共用緩衝）
A6: 每面場燈具數（盞） | B6: 12 | C6: 假設值，請照明廠商依照度計算
A7: 每面場大型吊扇數（台） | B7: 4 | C7: 假設值，100 吋級吊扇；改用 7.3 m HVLS 則 1–2 台
A9: 預算項目 | B9: 簡報預算｜1 面 | C9: 簡報預算｜2 面 | D9: 比價估算｜1 面（選用 Y 加總） | E9: 比價估算｜2 面 | F9: 差額｜1 面（預算－估算） | G9: 說明
A10: 運動地板 | B10: 500000 | C10: 1000000 | D10: =SUMIFS(比價清單!$I:$I,比價清單!$A:$A,"運動地板",比價清單!$K:$K,"Y") -> 172800 | E10: =SUMIFS(比價清單!$J:$J,比價清單!$A:$A,"運動地板",比價清單!$K:$K,"Y") -> 322560 | F10: =B10-D10 -> 327200 | G10: 比價只含材料；整平、彈性底層、施工另計，請地板廠商報價
A11: 網柱、球網、球具 | B11: 100000 | C11: 200000 | D11: =SUMIFS(比價清單!$I:$I,比價清單!$A:$A,"網柱與球網",比價清單!$K:$K,"Y")+SUMIFS(比價清單!$I:$I,比價清單!$A:$A,"球具",比價清單!$K:$K,"Y") -> 73200 | E11: =SUMIFS(比價清單!$J:$J,比價清單!$A:$A,"網柱與球網",比價清單!$K:$K,"Y")+SUMIFS(比價清單!$J:$J,比價清單!$A:$A,"球具",比價清單!$K:$K,"Y") -> 130950 | F11: =B11-D11 -> 26800 | G11: 球網、標誌桿、裁判台待報價
A12: 照明（LED、裝兩側） | B12: 150000 | C12: 250000 | D12: =SUMIFS(比價清單!$I:$I,比價清單!$A:$A,"照明",比價清單!$K:$K,"Y") -> 50160 | E12: =SUMIFS(比價清單!$J:$J,比價清單!$A:$A,"照明",比價清單!$K:$K,"Y") -> 100320 | F12: =B12-D12 -> 99840 | G12: 比價不含電工配線
A13: 通風、冷氣 | B13: 250000 | C13: 400000 | D13: =SUMIFS(比價清單!$I:$I,比價清單!$A:$A,"通風",比價清單!$K:$K,"Y") -> 146700 | E13: =SUMIFS(比價清單!$J:$J,比價清單!$A:$A,"通風",比價清單!$K:$K,"Y") -> 293400 | F13: =B13-D13 -> 103300 | G13: 比價只含吊扇本體；冷氣、排風、安裝另計
A14: 廁所、淋浴、更衣 | B14: 350000 | C14: 450000 | D14: 待廠商報價 | E14: 待廠商報價 | G14: 向水電、裝修廠商報價
A15: 休息區、櫃台、家具 | B15: 150000 | C15: 180000 | D15: 待廠商報價 | E15: 待廠商報價
A16: 法規變更、設計、消防 | B16: 200000 | C16: 250000 | D16: 待廠商報價 | E16: 待廠商報價 | G16: 建築師、消防設備師報價
A17: 系統、門禁、監視器 | B17: 100000 | C17: 150000 | D17: =SUMIFS(比價清單!$I:$I,比價清單!$A:$A,"系統",比價清單!$K:$K,"Y") -> 0 | E17: =SUMIFS(比價清單!$J:$J,比價清單!$A:$A,"系統",比價清單!$K:$K,"Y") -> 0 | F17: =B17-D17 -> 100000 | G17: 預約平台費用待洽詢
A18: 品牌與開幕行銷 | B18: 80000 | C18: 80000 | D18: 待廠商報價 | E18: 待廠商報價
A19: 安全設備（AED 等） | B19: 0 | C19: 0 | D19: =SUMIFS(比價清單!$I:$I,比價清單!$A:$A,"安全",比價清單!$K:$K,"Y") -> 73000 | E19: =SUMIFS(比價清單!$J:$J,比價清單!$A:$A,"安全",比價清單!$K:$K,"Y") -> 73000 | F19: =B19-D19 -> -73000 | G19: 簡報預算原本沒列，建議補 7–9 萬
A20: 合計 | B20: =SUM(B10:B19) -> 1880000 | C20: =SUM(C10:C19) -> 2960000 | D20: =SUM(D10:D19) -> 515860 | E20: =SUM(E10:E19) -> 920230 | F20: =SUM(F10:F19) -> 584140 | G20: 比價估算只涵蓋有網路價格的項目，不是完整開辦費

Sheet 比價清單
A1: 類別 | B1: 品項 | C1: 品牌／型號 | D1: 規格重點 | E1: 單價（元） | F1: 單位 | G1: 1 面數量 | H1: 2 面數量 | I1: 1 面小計 | J1: 2 面小計 | K1: 選用(Y) | L1: 通路／賣家 | M1: 連結 | N1: 查價日 | O1: 備註 | P1: 其他球館／參考
A2: 運動地板 | B2: PVC 運動地膠（寶石紋） | C2: 宜悅家居（網拍） | D2: 4.5 mm 捲材，可依尺寸訂製 | E2: 480 | F2: 元/㎡ | G2: =預算總表!$B$4 -> 360 | H2: =預算總表!$B$5 -> 672 | I2: =IF(E2="","待報價",E2*G2) -> 172800 | J2: =IF(E2="","待報價",E2*H2) -> 322560 | K2: Y | L2: 樂天市場 | M2: 開啟連結 | N2: 2026/10/21 | O2: 網拍等級，無運動認證資料；只含材料 | P2: 可利：Google 評論提到用 PU 地板
A3: 運動地板 | B3: PVC 運動地膠 | C3: 心語家居（網拍） | D3: 4.5 mm | E3: 423 | F3: 元/㎡ | G3: =預算總表!$B$4 -> 360 | H3: =預算總表!$B$5 -> 672 | I3: =IF(E3="","待報價",E3*G3) -> 152280 | J3: =IF(E3="","待報價",E3*H3) -> 284256 | L3: 蝦皮 | M3: 開啟連結 | N3: 2026/10/21 | O3: 網拍等級
A4: 運動地板 | B4: PVC 運動地膠 | C4: MM 居家（網拍） | D4: 3.5 mm，10 ㎡ 起訂 | E4: 419 | F4: 元/㎡ | G4: =預算總表!$B$4 -> 360 | H4: =預算總表!$B$5 -> 672 | I4: =IF(E4="","待報價",E4*G4) -> 150840 | J4: =IF(E4="","待報價",E4*H4) -> 281568 | L4: 蝦皮 | M4: 開啟連結 | N4: 2026/10/21 | O4: 3.5 mm 偏薄，排球救球建議 4.5 mm 以上（待與廠商確認）
A5: 運動地板 | B5: PU 運動地坪（PU 層） | C5: PRO360 師傅報價行情 | D5: 室內 PU 層，不含底層與面材 | E5: 650 | F5: 元/㎡ | G5: =預算總表!$B$4 -> 360 | H5: =預算總表!$B$5 -> 672 | I5: =IF(E5="","待報價",E5*G5) -> 234000 | J5: =IF(E5="","待報價",E5*H5) -> 436800 | L5: PRO360 | M5: 開啟連結 | N5: 2026/10/21 | O5: 行情價，非單一廠商報價
A6: 運動地板 | B6: 專業 PVC 運動地板 | C6: Enlio 英利奧 | D6: 國際品牌運動地板捲材 | F6: 元/㎡ | G6: =預算總表!$B$4 -> 360 | H6: =預算總表!$B$5 -> 672 | I6: =IF(E6="","待報價",E6*G6) -> 待報價 | J6: =IF(E6="","待報價",E6*H6) -> 待報價 | L6: 台灣經銷 | M6: 開啟連結 | N6: 2026/10/21 | O6: 需向經銷詢價
A7: 運動地板 | B7: 專業 PVC 運動地板 | C7: Gerflor Taraflex | D7: 原廠稱自 1976 年起為奧運地板供應商 | F7: 元/㎡ | G7: =預算總表!$B$4 -> 360 | H7: =預算總表!$B$5 -> 672 | I7: =IF(E7="","待報價",E7*G7) -> 待報價 | J7: =IF(E7="","待報價",E7*H7) -> 待報價 | L7: 原廠 | M7: 開啟連結 | N7: 2026/10/21 | O7: 需找台灣代理詢價 | P7: 國際賽事常用品牌
A8: 運動地板 | B8: 地板施工（整平、彈性底層、鋪設、畫線） | F8: 式 | G8: 1 | H8: 1 | I8: =IF(E8="","待報價",E8*G8) -> 待報價 | J8: =IF(E8="","待報價",E8*H8) -> 待報價 | L8: 地板廠商 | N8: 2026/10/21 | O8: 一定要另外報價
A9: 網柱與球網 | B9: 移動式比賽排球柱（不鏽鋼管、大滾輪） | C9: 必成體育 | D9: 一組，下單前需先詢問 | E9: 43500 | F9: 元/組 | G9: 1 | H9: 2 | I9: =IF(E9="","待報價",E9*G9) -> 43500 | J9: =IF(E9="","待報價",E9*H9) -> 87000 | L9: 蝦皮 | M9: 開啟連結 | N9: 2026/10/21
A10: 網柱與球網 | B10: 移動式比賽排球柱（鋁管、大滾輪） | C10: 必成體育 | D10: 一組，下單前需先詢問 | E10: 31500 | F10: 元/組 | G10: 1 | H10: 2 | I10: =IF(E10="","待報價",E10*G10) -> 31500 | J10: =IF(E10="","待報價",E10*H10) -> 63000 | K10: Y | L10: 蝦皮 | M10: 開啟連結 | N10: 2026/10/21
A11: 網柱與球網 | B11: 多功能比賽排球柱（移動式） | C11: 【專業器材】 | D11: 材質未標示 | E11: 17680 | F11: 元/組 | G11: 1 | H11: 2 | I11: =IF(E11="","待報價",E11*G11) -> 17680 | J11: =IF(E11="","待報價",E11*H11) -> 35360 | L11: 蝦皮 | M11: 開啟連結 | N11: 2026/10/21
A12: 網柱與球網 | B12: 不鏽鋼排球柱（7.6 cm 管徑） | C12: miracleshen | D12: 一組，不含運費 | E12: 14800 | F12: 元/組 | G12: 1 | H12: 2 | I12: =IF(E12="","待報價",E12*G12) -> 14800 | J12: =IF(E12="","待報價",E12*H12) -> 29600 | L12: 蝦皮 | M12: 開啟連結 | N12: 2026/10/21 | O12: 要確認能否調到男網 2.43 m／女網 2.24 m
A13: 網柱與球網 | B13: 比賽用排球網＋標誌桿 | F13: 組 | G13: 1 | H13: 2 | I13: =IF(E13="","待報價",E13*G13) -> 待報價 | J13: =IF(E13="","待報價",E13*H13) -> 待報價 | L13: 網柱廠商 | N13: 2026/10/21 | O13: 跟網柱一起報價
A14: 網柱與球網 | B14: 裁判台 | F14: 台 | G14: 1 | H14: 2 | I14: =IF(E14="","待報價",E14*G14) -> 待報價 | J14: =IF(E14="","待報價",E14*H14) -> 待報價 | L14: 網柱廠商 | N14: 2026/10/21 | O14: 跟網柱一起報價
A15: 球具 | B15: 比賽用球 V200W | C15: MIKASA | D15: FIVB 公認比賽球，5 號 | E15: 2700 | F15: 元/顆 | G15: 12 | H15: 20 | I15: =IF(E15="","待報價",E15*G15) -> 32400 | J15: =IF(E15="","待報價",E15*H15) -> 54000 | K15: Y | L15: Yahoo 拍賣 | M15: 開啟連結 | N15: 2026/10/21 | O15: 商品說明另寫 2,350 元，以賣家確認為準
A16: 球具 | B16: 練習用排球 4035 | C16: SUCCESS 成功 | D16: 5 號一般排球 | E16: 175 | F16: 元/顆 | G16: 20 | H16: 30 | I16: =IF(E16="","待報價",E16*G16) -> 3500 | J16: =IF(E16="","待報價",E16*H16) -> 5250 | K16: Y | L16: Yahoo 購物中心 | M16: 開啟連結 | N16: 2026/10/21 | O16: 新手課、臨打練習用
A17: 球具 | B17: 移動式球車 | C17: 5Cgo | D17: 鋼製、可拆、133×39.5×96 cm | E17: 2900 | F17: 元/台 | G17: 2 | H17: 3 | I17: =IF(E17="","待報價",E17*G17) -> 5800 | J17: =IF(E17="","待報價",E17*H17) -> 8700 | K17: Y | L17: Yahoo 拍賣 | M17: 開啟連結 | N17: 2026/10/21 | O17: 原為籃球車，排球可用
A18: 照明 | B18: LED 天井燈（撥碼 120–200 W） | C18: 舞光 戰神 D-HBCS200DP | D18: 瓦數可調 | E18: 4180 | F18: 元/盞 | G18: =預算總表!$B$6 -> 12 | H18: =預算總表!$B$6*2 -> 24 | I18: =IF(E18="","待報價",E18*G18) -> 50160 | J18: =IF(E18="","待報價",E18*H18) -> 100320 | K18: Y | L18: momo（BigGo 比價） | M18: 開啟連結 | N18: 2026/10/21 | O18: 在比價頁搜尋型號 | P18: 燈具裝在場地兩側，避開發球正上方
A19: 照明 | B19: LED 天井燈 200 W | C19: 億光 星辰 | E19: 5300 | F19: 元/盞 | G19: =預算總表!$B$6 -> 12 | H19: =預算總表!$B$6*2 -> 24 | I19: =IF(E19="","待報價",E19*G19) -> 63600 | J19: =IF(E19="","待報價",E19*H19) -> 127200 | L19: momo（BigGo 比價） | M19: 開啟連結 | N19: 2026/10/21 | O19: 在比價頁搜尋型號
A20: 照明 | B20: LED 天井燈 200 W | C20: 舞光 飛艦 D-HBAS200D | E20: 6930 | F20: 元/盞 | G20: =預算總表!$B$6 -> 12 | H20: =預算總表!$B$6*2 -> 24 | I20: =IF(E20="","待報價",E20*G20) -> 83160 | J20: =IF(E20="","待報價",E20*H20) -> 166320 | L20: Yahoo 購物中心（BigGo 比價） | M20: 開啟連結 | N20: 2026/10/21 | O20: 在比價頁搜尋型號
A21: 照明 | B21: LED 天井燈 150 W | C21: 台灣歐日光電 BA150C | D21: 內建風扇，保固 1 年 | E21: 3370 | F21: 元/盞 | G21: =預算總表!$B$6 -> 12 | H21: =預算總表!$B$6*2 -> 24 | I21: =IF(E21="","待報價",E21*G21) -> 40440 | J21: =IF(E21="","待報價",E21*H21) -> 80880 | L21: momo | M21: 開啟連結 | N21: 2026/10/21 | O21: 限時價，原價 4,400
A22: 照明 | B22: LED 天井燈 100／150／200 W | C22: Everlight 億光 | D22: 價格區間 2,890–3,920 | E22: 3920 | F22: 元/盞 | G22: =預算總表!$B$6 -> 12 | H22: =預算總表!$B$6*2 -> 24 | I22: =IF(E22="","待報價",E22*G22) -> 47040 | J22: =IF(E22="","待報價",E22*H22) -> 94080 | L22: momo | M22: 開啟連結 | N22: 2026/10/21 | O22: 取區間上限估
A23: 通風 | B23: DC 吊扇 100 吋（約 2.5 m） | C23: VENTO MEGA | E23: 36675 | F23: 元/台 | G23: =預算總表!$B$7 -> 4 | H23: =預算總表!$B$7*2 -> 8 | I23: =IF(E23="","待報價",E23*G23) -> 146700 | J23: =IF(E23="","待報價",E23*H23) -> 293400 | K23: Y | L23: momo（飛比比價） | M23: 開啟連結 | N23: 2026/10/21 | O23: 在比價頁搜尋型號；不含安裝
A24: 通風 | B24: 巨型工業吊扇 100 吋 | C24: 宅造印象 | E24: 31999 | F24: 元/台 | G24: =預算總表!$B$7 -> 4 | H24: =預算總表!$B$7*2 -> 8 | I24: =IF(E24="","待報價",E24*G24) -> 127996 | J24: =IF(E24="","待報價",E24*H24) -> 255992 | L24: 蝦皮商城（飛比比價） | M24: 開啟連結 | N24: 2026/10/21 | O24: 在比價頁搜尋型號；不含安裝
A25: 通風 | B25: HVLS 大型工業吊扇 7.3 m | F25: 台 | G25: 1 | H25: 2 | I25: =IF(E25="","待報價",E25*G25) -> 待報價 | J25: =IF(E25="","待報價",E25*H25) -> 待報價 | L25: 工業風扇廠商 | M25: 開啟連結 | N25: 2026/10/21 | O25: 網拍 1,207–5,280 元多為訂金或零件，請廠商連安裝報價
A26: 安全 | B26: AED | C26: 凱樂斯 HeartPlus II NT-381 | D26: 國產，區間 6.5–7 萬 | E26: 65000 | F26: 元/台 | G26: 1 | H26: 1 | I26: =IF(E26="","待報價",E26*G26) -> 65000 | J26: =IF(E26="","待報價",E26*H26) -> 65000 | K26: Y | L26: 經銷商 | M26: 開啟連結 | N26: 2026/10/21 | O26: 取區間下限；另有貼片、電池耗材
A27: 安全 | B27: AED | C27: NANOOM HeartPlus／HeartResQ | D27: 區間 7–8 萬 | E27: 70000 | F27: 元/台 | G27: 1 | H27: 1 | I27: =IF(E27="","待報價",E27*G27) -> 70000 | J27: =IF(E27="","待報價",E27*H27) -> 70000 | L27: 經銷商 | M27: 開啟連結 | N27: 2026/10/21 | O27: 取區間下限
A28: 安全 | B28: AED | C28: Philips HeartStart | D28: 區間 8–10 萬 | E28: 80000 | F28: 元/台 | G28: 1 | H28: 1 | I28: =IF(E28="","待報價",E28*G28) -> 80000 | J28: =IF(E28="","待報價",E28*H28) -> 80000 | L28: 經銷商 | M28: 開啟連結 | N28: 2026/10/21 | O28: 取區間下限
A29: 安全 | B29: AED | C29: Defibtech Lifeline | D29: 區間 8–10 萬 | E29: 80000 | F29: 元/台 | G29: 1 | H29: 1 | I29: =IF(E29="","待報價",E29*G29) -> 80000 | J29: =IF(E29="","待報價",E29*H29) -> 80000 | L29: 經銷商 | M29: 開啟連結 | N29: 2026/10/21 | O29: 取區間下限
A30: 安全 | B30: AED | C30: LIFEPAK CR2 | D30: 區間 8–15 萬 | E30: 80000 | F30: 元/台 | G30: 1 | H30: 1 | I30: =IF(E30="","待報價",E30*G30) -> 80000 | J30: =IF(E30="","待報價",E30*H30) -> 80000 | L30: 經銷商 | M30: 開啟連結 | N30: 2026/10/21 | O30: 取區間下限
A31: 安全 | B31: AED 壁掛收納箱 | D31: 區間 8,000–25,000 | E31: 8000 | F31: 元/個 | G31: 1 | H31: 1 | I31: =IF(E31="","待報價",E31*G31) -> 8000 | J31: =IF(E31="","待報價",E31*H31) -> 8000 | K31: Y | L31: 經銷商 | M31: 開啟連結 | N31: 2026/10/21 | O31: 取區間下限
A32: 系統 | B32: 線上預約報名系統 | C32: booknow | F32: 月 | G32: 12 | H32: 12 | I32: =IF(E32="","待報價",E32*G32) -> 待報價 | J32: =IF(E32="","待報價",E32*H32) -> 待報價 | L32: 洽詢 | M32: 開啟連結 | N32: 2026/10/21 | O32: 費用待洽詢 | P32: 龍蝦排球館在用
A33: 系統 | B33: 場館報名系統 | C33: 愛來運動 Aligh | F33: 月 | G33: 12 | H33: 12 | I33: =IF(E33="","待報價",E33*G33) -> 待報價 | J33: =IF(E33="","待報價",E33*H33) -> 待報價 | L33: 洽詢 | M33: 開啟連結 | N33: 2026/10/21 | O33: 費用待洽詢 | P33: 新莊 259 排球館在用

Sheet 地板方案比較
A1: 運動地板方案比較（材料費估算，元）
A3: 方案 | B3: 單價下限（元/㎡） | C3: 單價上限（元/㎡） | D3: 1 面材料費（下限） | E3: 1 面材料費（上限） | F3: 優點 | G3: 要注意 | H3: 連結
A4: 網拍 PVC 運動地膠（3.5–4.5 mm） | B4: 419 | C4: 545 | D4: =IF(B4="","待報價",B4*預算總表!$B$4) -> 150840 | E4: =IF(C4="","待報價",C4*預算總表!$B$4) -> 196200 | F4: 便宜、捲材好鋪、可自選顏色 | G4: 品質落差大、多半沒有運動認證或彈性底層資料；營業場館耐用度未知 | H4: 開啟連結
A5: PU 運動地坪（只算 PU 層） | B5: 650 | D5: =IF(B5="","待報價",B5*預算總表!$B$4) -> 234000 | E5: =IF(C5="","待報價",C5*預算總表!$B$4) -> 待報價 | F5: 無接縫、可直接畫線 | G5: 需要平整乾燥的底層；施工期較長、做了搬不走；上限要看底層與彈性層 | H5: 開啟連結
A6: 專業 PVC 運動地板（Enlio、Taraflex 等） | D6: =IF(B6="","待報價",B6*預算總表!$B$4) -> 待報價 | E6: =IF(C6="","待報價",C6*預算總表!$B$4) -> 待報價 | F6: 有運動地板系統與彈性層，國際賽事常用 | G6: 價格要向代理商詢價，通常含專業施工 | H6: 開啟連結
A7: 木地板（運動用） | D7: =IF(B7="","待報價",B7*預算總表!$B$4) -> 待報價 | E7: =IF(C7="","待報價",C7*預算總表!$B$4) -> 待報價 | F7: 腳感最好 | G7: 最貴，怕潮濕；倉庫改建要注意防潮
A10: 其他球館用什麼（目前查得到的）
A11: 球館 | B11: 地點 | C11: 已知的場地資訊 | D11: 資料來源 | H11: 連結
A12: 可利's 排球小棧 | B12: 寶山鄉大崎一路（近竹科） | C12: Google 評論提到 PU 地板、有冷氣 | D12: Google 地圖評論 | H12: 開啟連結
A13: 龍蝦排球館 | B13: 寶山鄉大崎一路 | C13: 打球區 25 × 18 m、休息區 5 m 深；評論提到挑高、有冷氣 | D13: 官網、Google 地圖評論 | H13: 開啟連結
A14: Volley Chill × 排丘 | B14: 寶山鄉大崎一路 | C14: 評論提到高度夠跳發；鋼柱和金屬邊角沒有包防撞 | D14: Google 地圖評論 | H14: 開啟連結
A15: 就醬瘋 JCV | B15: 園區二路（門牌屬寶山鄉大崎村） | C15: 評論提到挑高、明亮，也有人覺得燈太亮 | D15: Google 地圖評論 | H15: 開啟連結
A16: 啪！排郎 | B16: 竹北市中正西路 | C16: 地板資訊待踩點確認 | D16: Google 地圖 | H16: 開啟連結
A17: 新莊 259 排球館（參考） | B17: 新北市新莊區 | C17: 場地 17 × 24 m，兩側緩衝 2.7／5.3 m | D17: 愛來運動場館頁 | H17: 開啟連結
A19: 踩點時請順便記錄：地板品牌與厚度、哪家廠商施工、淨高、燈具位置、通風方式。

Sheet 廠商報價追蹤
A1: 類別 | B1: 廠商 | C1: 聯絡人 | D1: 電話／LINE | E1: 報價日期 | F1: 報價金額（元） | G1: 含稅？ | H1: 含施工？ | I1: 保固 | J1: 工期 | K1: 付款條件 | L1: 報價單連結 | M1: 備註
A2: 運動地板 | B2: 〇〇運動地板有限公司 | C2: 王先生 | D2: 0912-345-678 | E2: 2026/11/05 | F2: 520000 | G2: 是 | H2: 是 | I2: 2 年 | J2: 7 天 | K2: 訂金 30% | M2: 範例列，填完第一筆後可刪除
A3: 運動地板
A4: 運動地板
A5: 運動地板
A6: 照明（含配線）
A7: 照明（含配線）
A8: 照明（含配線）
A9: 通風／吊扇（含安裝）
A10: 通風／吊扇（含安裝）
A11: 通風／吊扇（含安裝）
A12: 冷氣
A13: 冷氣
A14: 冷氣
... A38: AED

Sheet 排球人口推估
A1: 大新竹排球人口推估（依年齡層、依地區）
A2: 方法：人口 × 年齡層比例 × 打排球比例 × 每月固定打比例 × 會付費去私人館比例。黃底都是假設值，問卷或官方年齡資料出來後直接替換。
A4: 年齡層 | B4: 佔總人口比例 | C4: 有在打排球的比例 | D4: 其中每月固定打 | E4: 其中會付費去私人館 | F4: 說明
A5: 15–24 歲 | B5: 0.105 | C5: 0.06 | D5: 0.4 | E5: 0.3 | F5: 學生多，常在學校或野場免費打，付費比例較低
A6: 25–34 歲 | B6: 0.135 | C6: 0.03 | D6: 0.45 | E6: 0.6 | F6: 竹科上班族主力，最願意付費包場、臨打
A7: 35–44 歲 | B7: 0.19 | C7: 0.015 | D7: 0.45 | E7: 0.55 | F7: 新竹這個年齡層人口多（扶幼比全國前二），但時間較少
A8: 45–64 歲 | B8: 0.294 | C8: 0.004 | D8: 0.5 | E8: 0.4 | F8: 人數多但打排球比例低
A9: 每人換算：付費固定球友比例 | B9: =SUMPRODUCT(B5:B8,C5:C8,D5:D8,E5:E8) -> 0.002790075 | F9: 年齡比例參考 2020 普查：新竹縣 15–64 歲約 72%、新竹市約 74%；15–64 再細分為假設值，可用內政部五歲年齡組資料替換
A10: 每人換算：有在打排球比例 | B10: =SUMPRODUCT(B5:B8,C5:C8) -> 0.014376
A11: 每人換算：每月固定打比例 | B11: =SUMPRODUCT(B5:B8,C5:C8,D5:D8) -> 0.006213
A13: 地區 | B13: 2020 普查人口 | C13: 最新戶籍人口（有資料者） | D13: 私人排球館（面） | E13: 有在打排球（推估） | F13: 每月固定打（推估） | G13: 付費固定球友（推估） | H13: 每面場對應球友
A14: 新竹縣 竹北市 | B14: 223017 | C14: 220808 | D14: 1 | E14: =B14*$B$10 -> 3206.0924 | F14: =B14*$B$11 -> 1385.6046 | G14: =B14*$B$9 -> 622.23416 | H14: =IF(D14=0,"沒有私人球館",G14/D14) -> 622.23416
A15: 新竹縣 竹東鎮 | B15: 106287 | C15: 97914 | D15: 0 | E15: =B15*$B$10 -> 1527.9819 | F15: =B15*$B$11 -> 660.36113 | G15: =B15*$B$9 -> 296.5487 | H15: =IF(D15=0,"沒有私人球館",G15/D15) -> 沒有私人球館
A16: 新竹縣 湖口鄉 | B16: 99774 | C16: 84920 | D16: 0 | E16: =B16*$B$10 -> 1434.351 | F16: =B16*$B$11 -> 619.89586 | G16: =B16*$B$9 -> 278.37694 | H16: =IF(D16=0,"沒有私人球館",G16/D16) -> 沒有私人球館
A17: 新竹縣 新豐鄉 | B17: 65910 | D17: 0 | E17: =B17*$B$10 -> 947.52216 | F17: =B17*$B$11 -> 409.49883 | G17: =B17*$B$9 -> 183.89384 | H17: =IF(D17=0,"沒有私人球館",G17/D17) -> 沒有私人球館
A18: 新竹縣 新埔鎮 | B18: 36085 | D18: 0 | E18: =B18*$B$10 -> 518.75796 | F18: =B18*$B$11 -> 224.1961 | G18: =B18*$B$9 -> 100.67986 | H18: =IF(D18=0,"沒有私人球館",G18/D18) -> 沒有私人球館
A19: 新竹縣 關西鎮 | B19: 29693 | D19: 0 | E19: =B19*$B$10 -> 426.86657 | F19: =B19*$B$11 -> 184.48261 | G19: =B19*$B$9 -> 82.845697 | H19: =IF(D19=0,"沒有私人球館",G19/D19) -> 沒有私人球館
A20: 新竹縣 芎林鄉 | B20: 22154 | D20: 0 | E20: =B20*$B$10 -> 318.4859 | F20: =B20*$B$11 -> 137.6428 | G20: =B20*$B$9 -> 61.811322 | H20: =IF(D20=0,"沒有私人球館",G20/D20) -> 沒有私人球館
A21: 新竹縣 寶山鄉 | B21: 19410 | D21: 9 | E21: =B21*$B$10 -> 279.03816 | F21: =B21*$B$11 -> 120.59433 | G21: =B21*$B$9 -> 54.155356 | H21: =IF(D21=0,"沒有私人球館",G21/D21) -> 6.0172618
A22: 新竹縣 橫山鄉 | B22: 11885 | D22: 0 | E22: =B22*$B$10 -> 170.85876 | F22: =B22*$B$11 -> 73.841505 | G22: =B22*$B$9 -> 33.160041 | H22: =IF(D22=0,"沒有私人球館",G22/D22) -> 沒有私人球館
A23: 新竹縣 北埔鄉 | B23: 7836 | D23: 0 | E23: =B23*$B$10 -> 112.65034 | F23: =B23*$B$11 -> 48.685068 | G23: =B23*$B$9 -> 21.863028 | H23: =IF(D23=0,"沒有私人球館",G23/D23) -> 沒有私人球館
A24: 新竹縣 尖石鄉 | B24: 5116 | D24: 0 | E24: =B24*$B$10 -> 73.547616 | F24: =B24*$B$11 -> 31.785708 | G24: =B24*$B$9 -> 14.274024 | H24: =IF(D24=0,"沒有私人球館",G24/D24) -> 沒有私人球館
A25: 新竹縣 峨眉鄉 | B25: 4112 | D25: 0 | E25: =B25*$B$10 -> 59.114112 | F25: =B25*$B$11 -> 25.547856 | G25: =B25*$B$9 -> 11.472788 | H25: =IF(D25=0,"沒有私人球館",G25/D25) -> 沒有私人球館
A26: 新竹縣 五峰鄉 | B26: 1884 | D26: 0 | E26: =B26*$B$10 -> 27.084384 | F26: =B26*$B$11 -> 11.705292 | G26: =B26*$B$9 -> 5.2565013 | H26: =IF(D26=0,"沒有私人球館",G26/D26) -> 沒有私人球館
A27: 新竹市 東區 | B27: 249873 | D27: 0 | E27: =B27*$B$10 -> 3592.1742 | F27: =B27*$B$11 -> 1552.4609 | G27: =B27*$B$9 -> 697.16441 | H27: =IF(D27=0,"沒有私人球館",G27/D27) -> 沒有私人球館
A28: 新竹市 北區 | B28: 153427 | D28: 0 | E28: =B28*$B$10 -> 2205.6666 | F28: =B28*$B$11 -> 953.24195 | G28: =B28*$B$9 -> 428.07284 | H28: =IF(D28=0,"沒有私人球館",G28/D28) -> 沒有私人球館
A29: 新竹市 香山區 | B29: 96168 | D29: 0 | E29: =B29*$B$10 -> 1382.5112 | F29: =B29*$B$11 -> 597.49178 | G29: =B29*$B$9 -> 268.31593 | H29: =IF(D29=0,"沒有私人球館",G29/D29) -> 沒有私人球館
A30: 大新竹合計 | B30: =SUM(B14:B29) -> 1132631 | D30: =SUM(D14:D29) -> 10 | E30: =SUM(E14:E29) -> 16282.703 | F30: =SUM(F14:F29) -> 7037.0364 | G30: =SUM(G14:G29) -> 3160.1254 | H30: =G30/D30 -> 316.01254
A32: 大新竹依年齡層拆解
A33: 年齡層 | B33: 人口（推估） | C33: 有在打排球 | D33: 每月固定打 | E33: 付費固定球友
A34: =A5 -> 15–24 歲 | B34: =$B$30*B5 -> 118926.26 | C34: =B34*C5 -> 7135.5753 | D34: =C34*D5 -> 2854.2301 | E34: =D34*E5 -> 856.26904
A35: =A6 -> 25–34 歲 | B35: =$B$30*B6 -> 152905.18 | C35: =B35*C6 -> 4587.1556 | D35: =C35*D6 -> 2064.22 | E35: =D35*E6 -> 1238.532
A36: =A7 -> 35–44 歲 | B36: =$B$30*B7 -> 215199.89 | C36: =B36*C7 -> 3227.9983 | D36: =C36*D7 -> 1452.5993 | E36: =D36*E7 -> 798.92959
A37: =A8 -> 45–64 歲 | B37: =$B$30*B8 -> 332993.51 | C37: =B37*C8 -> 1331.9741 | D37: =C37*D8 -> 665.98703 | E37: =D37*E8 -> 266.39481
A38: 合計 | B38: =SUM(B34:B37) -> 820024.84 | C38: =SUM(C34:C37) -> 16282.703 | D38: =SUM(D34:D37) -> 7037.0364 | E38: =SUM(E34:E37) -> 3160.1254
A40: 用現有球館容量校準（供給端）
A41: 新竹私人球館面數 | B41: =D30 -> 10 | C41: Threads 球友統計：可利 5、龍蝦 2、排丘 1、排郎 1、醬瘋 1
A42: 每面每月時段數（3 小時一場） | B42: 150 | C42: 平日 5 場＋假日 5 場
A43: 平均滿場率 | B43: 0.6 | C43: 假設值
A44: 每場人數 | B44: 13 | C44: 兩隊 12 人＋替補
...
